This problem has appeared after https://github.com/JetBrains/kotlin/commit/45e881f03f642740ef53024b0f3440352a47ccc4

The simple example:
```
fun case_16(x: Int?, y: Nothing?) {
    x ?: y!!
    x.inv() // OK before commit, unsafe call after
}
```

To details see the following failed tests (muted now):
- DiagnosticsTestSpecGenerated$NotLinked$Dfa$Neg.test11
- DiagnosticsTestSpecGenerated$NotLinked$Dfa$Neg.test15
- DiagnosticsTestSpecGenerated$NotLinked$Dfa$Neg.test32
- DiagnosticsTestSpecGenerated$NotLinked$Dfa$Pos.test33
- DiagnosticsTestSpecGenerated$NotLinked$Dfa$Pos.test35
- DiagnosticsTestSpecGenerated$NotLinked$Dfa$Pos.test36
- DiagnosticsTestSpecGenerated$NotLinked$Dfa$Pos.test37